<?xml version="1.0" encoding="UTF-8"?>
<!-- Generated by org.testng.reporters.JUnitReportReporter -->
<testsuite hostname="DESKTOP-BN3PUO8" failures="0" tests="3" name="tests.rest.TC004_UpdateIncident" time="10.312" errors="1" timestamp="2023-05-27T17:19:44 IST" skipped="2">
  <testcase classname="tests.rest.TC004_UpdateIncident" name="UpdateIncident" time="3.419">
    <skipped/>
  </testcase> <!-- UpdateIncident -->
  <system-out/>
  <testcase classname="tests.rest.TC004_UpdateIncident" name="UpdateIncident" time="3.426">
    <error type="java.lang.RuntimeException">
      <![CDATA[java.lang.RuntimeException
at lib.utils.HTMLReporter.reportRequest(HTMLReporter.java:102)
at lib.rest.RESTAssuredBase.verifyResponseCode(RESTAssuredBase.java:189)
at tests.rest.TC004_UpdateIncident.UpdateIncident(TC004_UpdateIncident.java:29)
at java.base/jdk.internal.reflect.NativeMethodAccessorImpl.invoke0(Native Method)
at java.base/jdk.internal.reflect.NativeMethodAccessorImpl.invoke(NativeMethodAccessorImpl.java:77)
at java.base/jdk.internal.reflect.DelegatingMethodAccessorImpl.invoke(DelegatingMethodAccessorImpl.java:43)
at java.base/java.lang.reflect.Method.invoke(Method.java:568)
at org.testng.internal.invokers.MethodInvocationHelper.invokeMethod(MethodInvocationHelper.java:135)
at org.testng.internal.invokers.TestInvoker.invokeMethod(TestInvoker.java:673)
at org.testng.internal.invokers.TestInvoker.retryFailed(TestInvoker.java:262)
at org.testng.internal.invokers.MethodRunner.runInSequence(MethodRunner.java:62)
at org.testng.internal.invokers.TestInvoker$MethodInvocationAgent.invoke(TestInvoker.java:945)
at org.testng.internal.invokers.TestInvoker.invokeTestMethods(TestInvoker.java:193)
at org.testng.internal.invokers.TestMethodWorker.invokeTestMethods(TestMethodWorker.java:146)
at org.testng.internal.invokers.TestMethodWorker.run(TestMethodWorker.java:128)
at java.base/java.util.ArrayList.forEach(ArrayList.java:1511)
at org.testng.TestRunner.privateRun(TestRunner.java:808)
at org.testng.TestRunner.run(TestRunner.java:603)
at org.testng.SuiteRunner.runTest(SuiteRunner.java:429)
at org.testng.SuiteRunner.runSequentially(SuiteRunner.java:423)
at org.testng.SuiteRunner.privateRun(SuiteRunner.java:383)
at org.testng.SuiteRunner.run(SuiteRunner.java:326)
at org.testng.SuiteRunnerWorker.runSuite(SuiteRunnerWorker.java:52)
at org.testng.SuiteRunnerWorker.run(SuiteRunnerWorker.java:95)
at org.testng.TestNG.runSuitesSequentially(TestNG.java:1249)
at org.testng.TestNG.runSuitesLocally(TestNG.java:1169)
at org.testng.TestNG.runSuites(TestNG.java:1092)
at org.testng.TestNG.run(TestNG.java:1060)
at org.testng.remote.AbstractRemoteTestNG.run(AbstractRemoteTestNG.java:115)
at org.testng.remote.RemoteTestNG.initAndRun(RemoteTestNG.java:251)
at org.testng.remote.RemoteTestNG.main(RemoteTestNG.java:77)
]]>
    </error>
  </testcase> <!-- UpdateIncident -->
  <system-out/>
  <testcase classname="tests.rest.TC004_UpdateIncident" name="UpdateIncident" time="3.467">
    <skipped/>
  </testcase> <!-- UpdateIncident -->
  <system-out/>
</testsuite> <!-- tests.rest.TC004_UpdateIncident -->
